Workbook

Sheet Bornite-Chalcocite
A1: No. | B1: As | C1: Ga | D1: S | E1: Ag | F1: Sb | G1: Cd | H1: Fe | I1: In | J1: Cu | K1: Sn | L1: Zn | M1: Pb | N1: Total | O1: Comment | P1: Location
A2: 66 | B2: 4.75 | C2: 0 | D2: 24.23 | E2: 0.0864 | F2: 0.0046 | G2: 0 | H2: 2.81 | I2: 0 | J2: 60.49 | K2: 0 | L2: 0.0422 | M2: 0.0616 | N2: 92.4749 | O2: CL-07 CuS digenite (light blue) | P2: Cligga Head
A3: 62 | B3: 1.24 | C3: 0 | D3: 22.14 | E3: 0.0503 | F3: 0 | G3: 0.0071 | H3: 0.8352 | I3: 0 | J3: 68.11 | K3: 0 | L3: 0.0532 | M3: 0.0669 | N3: 92.5028 | O3: CL-07 CuS digenite (light blue) | P3: Cligga Head
A4: 60 | B4: 0.5755 | C4: 0 | D4: 20.39 | E4: 0.0703 | F4: 0 | G4: 0 | H4: 0.5392 | I4: 0 | J4: 71.9 | K4: 0 | L4: 0.0454 | M4: 0.0549 | N4: 93.5754 | O4: CL-07 CuS digenite (light blue) | P4: Cligga Head
A5: 61 | B5: 0.3056 | C5: 0 | D5: 20.32 | E5: 0.0473 | F5: 0 | G5: 0.0015 | H5: 0.2955 | I5: 0 | J5: 72.77 | K5: 0.005 | L5: 0.0643 | M5: 0.0502 | N5: 93.8595 | O5: CL-07 CuS digenite (light blue) | P5: Cligga Head
A6: 64 | B6: 0.8355 | C6: 0 | D6: 23.12 | E6: 0.0505 | F6: 0 | G6: 0 | H6: 0.4906 | I6: 0 | J6: 69.72 | K6: 0 | L6: 0.0428 | M6: 0.0364 | N6: 94.2959 | O6: CL-07 CuS digenite (light blue) | P6: Cligga Head
A7: 58 | B7: 0.4014 | C7: 0 | D7: 21.93 | E7: 0.0819 | F7: 0 | G7: 0.0012 | H7: 0.3348 | I7: 0 | J7: 71.57 | K7: 0 | L7: 0.0699 | M7: 0.049 | N7: 94.4383 | O7: CL-07 CuS digenite (light blue) | P7: Cligga Head
A8: 65 | B8: 0.6175 | C8: 0 | D8: 23.12 | E8: 0.0899 | F8: 0.0154 | G8: 0 | H8: 0.5178 | I8: 0 | J8: 71 | K8: 0.0003 | L8: 0.0686 | M8: 0.072 | N8: 95.5015 | O8: CL-07 CuS digenite (light blue) | P8: Cligga Head
A9: 63 | B9: 0.2326 | C9: 0 | D9: 29.51 | E9: 0.0816 | F9: 0 | G9: 0.0001 | H9: 0.2304 | I9: 0 | J9: 65.64 | K9: 0 | L9: 0.0222 | M9: 0.0702 | N9: 95.7872 | O9: CL-07 CuS digenite (light blue) | P9: Cligga Head
A10: 59 | B10: 1.21 | C10: 0 | D10: 23.64 | E10: 0.0512 | F10: 0 | G10: 0.0009 | H10: 0.7375 | I10: 0 | J10: 70.54 | K10: 0 | L10: 0.0296 | M10: 0.0486 | N10: 96.2579 | O10: CL-07 CuS digenite (light blue) | P10: Cligga Head
A11: 67 | B11: 0.6033 | C11: 0 | D11: 23.17 | E11: 0.0444 | F11: 0 | G11: 0 | H11: 0.4181 | I11: 0 | J11: 71.96 | K11: 0 | L11: 0.0646 | M11: 0.0458 | N11: 96.3063 | O11: CL-07 CuS digenite (light blue) | P11: Cligga Head
A12: 69 | B12: 1.05 | C12: 0 | D12: 25.15 | E12: 0.1542 | F12: 0 | G12: 0 | H12: 1 | I12: 0 | J12: 63.62 | K12: 0 | L12: 0.0558 | M12: 0.064 | N12: 91.0941 | O12: CL-07 CuS pink (in digenite) | P12: Cligga Head
A13: 56 | B13: 5.37 | C13: 0 | D13: 23.46 | E13: 0.0851 | F13: 0.0048 | G13: 0 | H13: 3.25 | I13: 0 | J13: 60.68 | K13: 0 | L13: 0.0354 | M13: 0.0361 | N13: 92.9215 | O13: CL-07 CuS(Fe,As) light blue coating? | P13: Cligga Head
... A142: 14 | B142: 0 | C142: 0 | D142: 27.66 | E142: 0.0354 | F142: 0.0017 | G142: 0 | H142: 1.25 | I142: 0 | J142: 71.2 | K142: 0 | L142: 0.0443 | M142: 0.0905 | N142: 100.2818 | O142: CW-05 Cu-bearing rim | P142: Great Condurrow

Sheet Tetrahedrite-Tennantite
A1: No. | B1: As | C1: Ga | D1: S | E1: Ag | F1: Sb | G1: Cd | H1: Fe | I1: In | J1: Cu | K1: Sn | L1: Zn | M1: Pb | N1: Total | O1: Sample | P1: Location
A2: 17 | B2: 19.78 | C2: 0 | D2: 33.62 | E2: 0.0063 | F2: 0.1052 | G2: 0.0013 | H2: 1.06 | I2: 0 | J2: 48.57 | K2: 0.0344 | L2: 0.0333 | M2: 0.1015 | N2: 103.312 | O2: RJS-BK4 Cu-As-S | P2: Botallack
A3: 18 | B3: 19.88 | C3: 0 | D3: 33.8 | E3: 0 | F3: 0 | G3: 0 | H3: 0.6902 | I3: 0 | J3: 48.47 | K3: 0.1453 | L3: 0.0262 | M3: 0.1086 | N3: 103.1202 | O3: RJS-BK4 Cu-As-S | P3: Botallack
A4: 12 | B4: 19.96 | C4: 0 | D4: 33.83 | E4: 0 | F4: 0 | G4: 0 | H4: 0.7873 | I4: 0 | J4: 48.22 | K4: 0.1871 | L4: 0.0503 | M4: 0.0998 | N4: 103.1345 | O4: RJS-BK4-Cu-As-S | P4: Botallack
A5: 253 | B5: 18.56 | C5: 0 | D5: 29.28 | E5: 0.059 | F5: 0 | G5: 0.1506 | H5: 3.1 | I5: 0.0454 | J5: 42.44 | K5: 0 | L5: 6.08 | M5: 0.8009 | N5: 100.5158 | O5: RJS-GV12 CuS? | P5: Geevor
A6: 254 | B6: 17.43 | C6: 0 | D6: 29.89 | E6: 0.032 | F6: 0.0015 | G6: 0.116 | H6: 4.85 | I6: 0.0392 | J6: 42.27 | K6: 0 | L6: 4.37 | M6: 1.28 | N6: 100.2786 | O6: RJS-GV12 CuS? | P6: Geevor
A7: 13 | B7: 21.76 | C7: 0 | D7: 31.11 | E7: 0.0525 | F7: 0.0548 | G7: 0.1106 | H7: 6.22 | I7: 0.0218 | J7: 40.12 | K7: 0 | L7: 1.69 | M7: 0.0775 | N7: 101.2172 | O7: RJS-BK4-Cu-As-S | P7: Botallack
A8: 15 | B8: 23.27 | C8: 0 | D8: 32.78 | E8: 0.011 | F8: 0.168 | G8: 0.0048 | H8: 4.27 | I8: 0.0299 | J8: 35.75 | K8: 0 | L8: 1.11 | M8: 0.0868 | N8: 97.4806 | O8: RJS-BK4 Cu-As-S | P8: Botallack
A9: 99 | B9: 9.09 | C9: 0 | D9: 24.95 | E9: 1.17 | F9: 12.64 | G9: 0 | H9: 9.43 | I9: 0 | J9: 34.69 | K9: 0.0731 | L9: 2.57 | M9: 0.0864 | N9: 94.6996 | O9: RJS-WC-02 stannite | P9: Wheal Charlotte
A10: 97 | B10: 9.39 | C10: 0 | D10: 23.6 | E10: 1.15 | F10: 12.12 | G10: 0 | H10: 7.86 | I10: 0 | J10: 35.04 | K10: 0 | L10: 1.94 | M10: 0.0845 | N10: 91.1846 | O10: RJS-WC-02 stannite | P10: Wheal Charlotte
A11: 4 | B11: 19.2 | C11: 0 | D11: 32.6 | E11: 0 | F11: 0 | G11: 0 | H11: 0.423 | I11: 0 | J11: 50.29 | K11: 0 | L11: 0.0504 | M11: 0 | N11: 102.5633 | O11: CW-06 cct | P11: Great Condurrow

Sheet Löllingite
A1: No. | B1: As | C1: Ga | D1: S | E1: Ag | F1: Sb | G1: Cd | H1: Fe | I1: In | J1: Cu | K1: Sn | L1: Zn | M1: Pb | N1: Total | O1: Sample | P1: Location
A2: 22 | B2: 66.63 | C2: 0 | D2: 4.24 | E2: 0.0326 | F2: 0 | G2: 0 | H2: 28.84 | I2: 0 | J2: 0.0108 | K2: 0 | L2: 0.0266 | M2: 0.0201 | N2: =SUM(B2:M2) -> 99.8001 | O2: RED-03-Lollingite | P2: Redmoor
A3: 83 | B3: 72.23 | C3: 0 | D3: 1.76 | E3: 0.0042 | F3: 0.0191 | G3: 0 | H3: 29.43 | I3: 0 | J3: 0.0106 | K3: 0 | L3: 0 | M3: 0.0262 | N3: 103.48 | O3: RM82-21-274.6 lollingite | P3: Redmoor
A4: 31 | B4: 71.95 | C4: 0 | D4: 1.71 | E4: 0.0067 | F4: 0 | G4: 0 | H4: 29.69 | I4: 0 | J4: 0 | K4: 0 | L4: 0 | M4: 0.0408 | N4: 103.3974 | O4: RM82-21-273 lollingite | P4: Redmoor
A5: 92 | B5: 71.8 | C5: 0 | D5: 2.26 | E5: 0 | F5: 0 | G5: 0 | H5: 29.65 | I5: 0 | J5: 0.0034 | K5: 0 | L5: 0 | M5: 0.0364 | N5: 103.7498 | O5: RM82-21-274.6 lollingite | P5: Redmoor
A6: 68 | B6: 71.47 | C6: 0 | D6: 2.52 | E6: 0.0105 | F6: 0.003 | G6: 0 | H6: 29.69 | I6: 0 | J6: 0.0116 | K6: 0 | L6: 0.0031 | M6: 0.0268 | N6: 103.7349 | O6: RM82-21-273 lollingite | P6: Redmoor
A7: 33 | B7: 71.36 | C7: 0 | D7: 2.59 | E7: 0 | F7: 0 | G7: 0 | H7: 30.14 | I7: 0 | J7: 0 | K7: 0 | L7: 0 | M7: 0.0122 | N7: 104.1021 | O7: RM82-21-273 lollingite | P7: Redmoor
A8: 43 | B8: 71.25 | C8: 0 | D8: 2.86 | E8: 0 | F8: 0 | G8: 0 | H8: 29.88 | I8: 0 | J8: 0.0111 | K8: 0 | L8: 0 | M8: 0.0364 | N8: 104.0374 | O8: RM82-21-273 lollingite | P8: Redmoor
A9: 56 | B9: 71.24 | C9: 0 | D9: 2.45 | E9: 0 | F9: 0 | G9: 0.0046 | H9: 29.81 | I9: 0 | J9: 0 | K9: 0 | L9: 0 | M9: 0.0382 | N9: 103.5427 | O9: RM82-21-273 lollingite | P9: Redmoor
A10: 69 | B10: 71.2 | C10: 0 | D10: 2.71 | E10: 0.0069 | F10: 0 | G10: 0 | H10: 29.81 | I10: 0.0001 | J10: 0.012 | K10: 0 | L10: 0 | M10: 0.0316 | N10: 103.7705 | O10: RM82-21-273 lollingite | P10: Redmoor
A11: 91 | B11: 71.12 | C11: 0 | D11: 2.75 | E11: 0.0051 | F11: 0 | G11: 0 | H11: 29.88 | I11: 0 | J11: 0 | K11: 0 | L11: 0.0152 | M11: 0.0335 | N11: 103.8037 | O11: RM82-21-274.6 lollingite | P11: Redmoor
A12: 55 | B12: 71.08 | C12: 0 | D12: 2.62 | E12: 0.0063 | F12: 0 | G12: 0 | H12: 30.04 | I12: 0 | J12: 0 | K12: 0 | L12: 0.0002 | M12: 0.0373 | N12: 103.7838 | O12: RM82-21-273 lollingite | P12: Redmoor
A13: 32 | B13: 71.05 | C13: 0 | D13: 2.78 | E13: 0 | F13: 0 | G13: 0 | H13: 30.47 | I13: 0 | J13: 0.0081 | K13: 0 | L13: 0.0156 | M13: 0.0085 | N13: 104.3322 | O13: RM82-21-273 lollingite | P13: Redmoor
A14: 84 | B14: 70.97 | C14: 0 | D14: 2.72 | E14: 0 | F14: 0 | G14: 0 | H14: 29.57 | I14: 0 | J14: 0 | K14: 0 | L14: 0.0015 | M14: 0.047 | N14: 103.3084 | O14: RM82-21-274.6 lollingite | P14: Redmoor
... A43: 25 | B43: 73.89 | C43: 0 | D43: 1.62 | E43: 0 | F43: 0.0038 | G43: 0 | H43: 28.59 | I43: 0 | J43: 0.0092 | K43: 0 | L43: 0 | M43: 0.0071 | N43: 104.1201 | O43: CW-06 cst | P43: Great Condurrow

Sheet Arsenopyrite
A1: No. | B1: As | C1: Ga | D1: S | E1: Ag | F1: Sb | G1: Cd | H1: Fe | I1: In | J1: Cu | K1: Sn | L1: Zn | M1: Pb | N1: Total | O1: Sample | P1: Location
A2: 31 | B2: 47.09 | C2: 0 | D2: 20.62 | E2: 0.0033 | F2: 0 | G2: 0 | H2: 36.25 | I2: 0 | J2: 0.007 | K2: 0 | L2: 0.0767 | M2: 0.0681 | N2: 104.1151 | O2: WC-01 arsenopyrite | P2: Wheal Charlotte
A3: 32 | B3: 47.31 | C3: 0 | D3: 20.37 | E3: 0 | F3: 0.0031 | G3: 0 | H3: 36.08 | I3: 0 | J3: 0 | K3: 0 | L3: 0.0125 | M3: 0.0723 | N3: 103.8478 | O3: WC-01 arsenopyrite | P3: Wheal Charlotte
A4: 33 | B4: 47.39 | C4: 0 | D4: 20.57 | E4: 0 | F4: 0 | G4: 0 | H4: 36.2 | I4: 0 | J4: 0 | K4: 0 | L4: 0.0604 | M4: 0.0911 | N4: 104.3115 | O4: WC-01 arsenopyrite | P4: Wheal Charlotte
A5: 34 | B5: 47.56 | C5: 0 | D5: 20.32 | E5: 0.003 | F5: 0.0353 | G5: 0 | H5: 35.81 | I5: 0 | J5: 0 | K5: 0 | L5: 0.0911 | M5: 0.0915 | N5: 103.9109 | O5: WC-01 arsenopyrite | P5: Wheal Charlotte
A6: 35 | B6: 47.28 | C6: 0 | D6: 20.58 | E6: 0 | F6: 0 | G6: 0 | H6: 35.73 | I6: 0 | J6: 0.0179 | K6: 0 | L6: 0.0123 | M6: 0.0883 | N6: 103.7084 | O6: WC-01 arsenopyrite | P6: Wheal Charlotte
A7: 8 | B7: 47.41 | C7: 0 | D7: 20.1 | E7: 0 | F7: 0 | G7: 0.0015 | H7: 35.96 | I7: 0 | J7: 0.0055 | K7: 0 | L7: 0.0042 | M7: 0.0492 | N7: 103.5304 | O7: RM82-25-185.6 lollingite | P7: Redmoor
A8: 6 | B8: 47.29 | C8: 0 | D8: 19.85 | E8: 0.008 | F8: 0.0007 | G8: 0 | H8: 36.25 | I8: 0 | J8: 0 | K8: 0 | L8: 0.0146 | M8: 0.058 | N8: 103.4713 | O8: RM82-25-185.6 lollingite | P8: Redmoor
A9: 7 | B9: 47.28 | C9: 0 | D9: 20.04 | E9: 0.0022 | F9: 0.0076 | G9: 0 | H9: 36.1 | I9: 0 | J9: 0.0036 | K9: 0 | L9: 0 | M9: 0.0546 | N9: 103.4879 | O9: RM82-25-185.6 lollingite | P9: Redmoor
A10: 80 | B10: 49.14 | C10: 0 | D10: 18.79 | E10: 0 | F10: 0.0178 | G10: 0 | H10: 35.37 | I10: 0 | J10: 0 | K10: 0 | L10: 0 | M10: 0.0324 | N10: 103.3501 | O10: RM82-21-274.6 arsenopyrite | P10: Redmoor
A11: 122 | B11: 48.81 | C11: 0 | D11: 19.17 | E11: 0 | F11: 0.0187 | G11: 0 | H11: 35.87 | I11: 0 | J11: 0 | K11: 0 | L11: 0 | M11: 0.0561 | N11: 103.9247 | O11: RM82-21-274.6 arsenopyrite | P11: Redmoor
A12: 121 | B12: 48.61 | C12: 0 | D12: 19.34 | E12: 0.0063 | F12: 0.1102 | G12: 0 | H12: 35.61 | I12: 0 | J12: 0.0086 | K12: 0 | L12: 0 | M12: 0.0768 | N12: 103.7618 | O12: RM82-21-274.6 arsenopyrite | P12: Redmoor
A13: 94 | B13: 48.59 | C13: 0 | D13: 19.31 | E13: 0.009 | F13: 0.0703 | G13: 0 | H13: 35.55 | I13: 0 | J13: 0 | K13: 0 | L13: 0 | M13: 0.0506 | N13: 103.5798 | O13: RM82-21-274.6 arsenopyrite | P13: Redmoor
... A127: 51 | B127: 48.8 | C127: 0 | D127: 19.04 | E127: 0 | F127: 0 | G127: 0 | H127: 35.09 | I127: 0 | J127: 0.009 | K127: 0 | L127: 0 | M127: 0.0662 | N127: 103.0051 | O127: CL-07 arsenopyrite | P127: Cligga Head
A128: 35 | B128: 40.75 | C128: 0 | D128: 24.48 | E128: 0.0083 | F128: 0.0131 | G128: 0 | H128: 36.92 | I128: 0 | J128: 0.0096 | K128: 0 | L128: 0 | M128: 0.1058 | N128: 102.2867 | O128: 3JD4-arsenopyrite
A129: 72 | B129: 46.28 | C129: 0 | D129: 20.44 | E129: 0 | F129: 0.0006 | G129: 0 | H129: 39.47 | I129: 0 | J129: 0.0052 | K129: 0 | L129: 0 | M129: 0.0965 | N129: 106.2923 | O129: DC-03 arsenopyrite | P129: Dolcoath
A130: 73 | B130: 46.26 | C130: 0 | D130: 20.16 | E130: 0.0014 | F130: 0.0164 | G130: 0 | H130: 39.35 | I130: 0 | J130: 0 | K130: 0 | L130: 0.0079 | M130: 0.1014 | N130: 105.897 | O130: DC-03 arsenopyrite | P130: Dolcoath
A131: 60 | B131: 45.9 | C131: 0 | D131: 20.44 | E131: 0.0077 | F131: 0.0355 | G131: 0 | H131: 39.29 | I131: 0 | J131: 0 | K131: 0 | L131: 0.0062 | M131: 0.084 | N131: 105.7634 | O131: DC-03 arsenopyrite | P131: Dolcoath
A132: 65 | B132: 46.69 | C132: 0 | D132: 19.99 | E132: 0.0014 | F132: 0.0088 | G132: 0 | H132: 39.14 | I132: 0 | J132: 0 | K132: 0 | L132: 0 | M132: 0.0935 | N132: 105.9236 | O132: DC-03 arsenopyrite | P132: Dolcoath
A133: 70 | B133: 46.43 | C133: 0 | D133: 20.27 | E133: 0.0036 | F133: 0 | G133: 0.0014 | H133: 39.12 | I133: 0 | J133: 0.005 | K133: 0 | L133: 0 | M133: 0.0931 | N133: 105.923 | O133: DC-03 arsenopyrite | P133: Dolcoath
A134: 45 | B134: 48.64 | C134: 0 | D134: 19.23 | E134: 0.0083 | F134: 0 | G134: 0 | H134: 35.84 | I134: 0 | J134: 0 | K134: 0 | L134: 0.0137 | M134: 0.0742 | N134: 103.8061 | O134: 21-315.6 arsenopyrite | P134: Redmoor
A135: 115 | B135: 47.67 | C135: 0 | D135: 20.3 | E135: 0 | F135: 0 | G135: 0 | H135: 35.75 | I135: 0 | J135: 0.0075 | K135: 0 | L135: 0 | M135: 0.0806 | N135: 103.808 | O135: 206-208. | P135: Redmoor
A136: 44 | B136: 47.85 | C136: 0 | D136: 19.33 | E136: 0.0068 | F136: 0.0376 | G136: 0 | H136: 35.66 | I136: 0 | J136: 0 | K136: 0 | L136: 0 | M136: 0.0708 | N136: 102.9551 | O136: 21-315.6 arsenopyrite | P136: Redmoor
A137: 39 | B137: 46.55 | C137: 0 | D137: 20.88 | E137: 0.0035 | F137: 0.0056 | G137: 0 | H137: 35.64 | I137: 0 | J137: 0.013 | K137: 0 | L137: 0 | M137: 0.0863 | N137: 103.1784 | O137: 21-315.6 arsenopyrite | P137: Redmoor
A138: 99 | B138: 48.47 | C138: 0 | D138: 19.4 | E138: 0.0323 | F138: 0 | G138: 0 | H138: 35.6 | I138: 0 | J138: 0 | K138: 0 | L138: 0 | M138: 0.0887 | N138: 103.591 | O138: 206-208. | P138: Redmoor
A139: 160 | B139: 48.95 | C139: 0 | D139: 18.94 | E139: 0 | F139: 0 | G139: 0.0029 | H139: 35.51 | I139: 0 | J139: 0.0006 | K139: 0 | L139: 0 | M139: 0.0568 | N139: 103.4602 | O139: 202 | P139: Redmoor
A140: 40 | B140: 47.65 | C140: 0 | D140: 19.53 | E140: 0 | F140: 0 | G140: 0 | H140: 35.47 | I140: 0 | J140: 0 | K140: 0 | L140: 0 | M140: 0.0805 | N140: 102.7304 | O140: 21-315.6 arsenopyrite | P140: Redmoor
A141: 159 | B141: 47.93 | C141: 0 | D141: 19.65 | E141: 0 | F141: 0 | G141: 0.0001 | H141: 35.39 | I141: 0 | J141: 0 | K141: 0 | L141: 0.0028 | M141: 0.0815 | N141: 103.0543 | O141: 202 | P141: Redmoor
A142: 92 | B142: 49.88 | C142: 0 | D142: 18.57 | E142: 0 | F142: 0 | G142: 0 | H142: 35.32 | I142: 0 | J142: 0.013 | K142: 0 | L142: 0 | M142: 0.0676 | N142: 103.8505 | O142: 206-208. | P142: Redmoor
A143: 117 | B143: 48.47 | C143: 0 | D143: 19.29 | E143: 0 | F143: 0 | G143: 0 | H143: 35.07 | I143: 0 | J143: 0.0199 | K143: 0 | L143: 0.016 | M143: 0.09 | N143: 102.9558 | O143: 206-208. | P143: Redmoor
A144: 158 | B144: 49.12 | C144: 0 | D144: 18.84 | E144: 0.0105 | F144: 0 | G144: 0 | H144: 34.99 | I144: 0 | J144: 0 | K144: 0 | L144: 0.0021 | M144: 0.0853 | N144: 103.0478 | O144: 202 | P144: Redmoor
A145: 116 | B145: 48.32 | C145: 0 | D145: 19.43 | E145: 0 | F145: 0 | G145: 0.0028 | H145: 34.82 | I145: 0 | J145: 0 | K145: 0 | L145: 0 | M145: 0.1022 | N145: 102.6749 | O145: 206-208. | P145: Redmoor
A146: 162 | B146: 54.36 | C146: 0 | D146: 15.43 | E146: 0 | F146: 0 | G146: 0 | H146: 34.08 | I146: 0 | J146: 0 | K146: 0 | L146: 0.0089 | M146: 0.0657 | N146: 103.9445 | O146: 202 | P146: Redmoor
A147: 44 | B147: 46.99 | C147: 0 | D147: 19.98 | E147: 0 | F147: 0 | G147: 0 | H147: 34.07 | I147: 0 | J147: 0 | K147: 0 | L147: 0 | M147: 0.093 | N147: 101.1329 | O147: HD-03 ? | P147: Hingston Down
A148: 39 | B148: 47.66 | C148: 0 | D148: 19.49 | E148: 0 | F148: 0 | G148: 0 | H148: 33.71 | I148: 0.0025 | J148: 0 | K148: 0 | L148: 0.0129 | M148: 0.0807 | N148: 100.9561 | O148: HD-03 ccp | P148: Hingston Down
A149: 40 | B149: 48.33 | C149: 0 | D149: 18.95 | E149: 0 | F149: 0 | G149: 0 | H149: 33.8 | I149: 0 | J149: 0.0055 | K149: 0 | L149: 0 | M149: 0.1004 | N149: 101.1859 | O149: HD-03 ccp | P149: Hingston Down
A150: 35 | B150: 48.47 | C150: 0 | D150: 19.22 | E150: 0 | F150: 0.0762 | G150: 0 | H150: 33.92 | I150: 0 | J150: 0.0145 | K150: 0 | L150: 0.7828 | M150: 0.0991 | N150: 102.5826 | O150: MP-04-? | P150: Red-a-Ven
A151: 41 | B151: 48.84 | C151: 0 | D151: 18.63 | E151: 0.0037 | F151: 0 | G151: 0 | H151: 33.48 | I151: 0 | J151: 0.0029 | K151: 0 | L151: 0.0133 | M151: 0.0887 | N151: 101.0585 | O151: HD-03 ccp | P151: Hingston Down
A152: 8 | B152: 45.91 | C152: 0 | D152: 21.44 | E152: 0 | F152: 0.0173 | G152: 0 | H152: 35.6 | I152: 0 | J152: 0 | K152: 0 | L152: 0 | M152: 0.0943 | N152: 103.0615 | O152: DGC-04 apy | P152: Devon Great Consols
A153: 9 | B153: 46.21 | C153: 0 | D153: 21.23 | E153: 0 | F153: 0.003 | G153: 0 | H153: 35.95 | I153: 0 | J153: 0 | K153: 0 | L153: 0 | M153: 0.0783 | N153: 103.4713 | O153: DGC-04 apy | P153: Devon Great Consols
...

Sheet Pyrite
A1: No. | B1: As | C1: Ga | D1: S | E1: Ag | F1: Sb | G1: Cd | H1: Fe | I1: In | J1: Cu | K1: Sn | L1: Zn | M1: Pb | N1: Total | O1: Sample | P1: Location
A2: 30 | B2: 0.0032 | C2: 0 | D2: 54.11 | E2: 0.0198 | F2: 0.0008 | G2: 0 | H2: 49.1 | I2: 0.0013 | J2: 0.0084 | K2: 0 | L2: 0 | M2: 0.1752 | N2: 103.4186 | O2: 21-315.6 pyrite | P2: Redmoor
A3: 28 | B3: 0.0584 | C3: 0 | D3: 54.44 | E3: 0.0173 | F3: 0 | G3: 0 | H3: 48.72 | I3: 0 | J3: 0.0551 | K3: 0 | L3: 0 | M3: 0.2004 | N3: 103.4911 | O3: 21-315.6 pyrite | P3: Redmoor
A4: 29 | B4: 0.0135 | C4: 0 | D4: 54.49 | E4: 0.0088 | F4: 0 | G4: 0 | H4: 48.62 | I4: 0 | J4: 0.0216 | K4: 0 | L4: 0 | M4: 0.1891 | N4: 103.3429 | O4: 21-315.6 pyrite | P4: Redmoor
A5: 36 | B5: 0.0136 | C5: 0 | D5: 54.3 | E5: 0.0029 | F5: 0 | G5: 0 | H5: 48.26 | I5: 0.0003 | J5: 0 | K5: 0 | L5: 0.0019 | M5: 0.1761 | N5: 102.7547 | O5: 21-315.6 pyrite | P5: Redmoor
A6: 10 | B6: 0.1416 | C6: 0 | D6: 54.24 | E6: 0.0196 | F6: 0.0041 | G6: 0 | H6: 47.97 | I6: 0 | J6: 0.0191 | K6: 0 | L6: 0 | M6: 0.2393 | N6: 102.6337 | O6: 21-315.6 pyrite | P6: Redmoor
A7: 37 | B7: 0.0068 | C7: 0 | D7: 54.08 | E7: 0.0121 | F7: 0.0053 | G7: 0 | H7: 47.92 | I7: 0.0027 | J7: 0.0041 | K7: 0 | L7: 0.0024 | M7: 0.1745 | N7: 102.2078 | O7: 21-315.6 pyrite | P7: Redmoor
A8: 61 | B8: 0.0001 | C8: 0 | D8: 54.28 | E8: 0 | F8: 0 | G8: 0 | H8: 48.24 | I8: 0 | J8: 0 | K8: 0 | L8: 0 | M8: 0.2077 | N8: 102.7277 | O8: 29-636 pyrite | P8: Redmoor
A9: 49 | B9: 0 | C9: 0 | D9: 54.3 | E9: 0.0043 | F9: 0 | G9: 0 | H9: 48.2 | I9: 0 | J9: 0.1376 | K9: 0 | L9: 0.0205 | M9: 0.2069 | N9: 102.8693 | O9: 29-636 pyrite | P9: Redmoor
A10: 62 | B10: 0 | C10: 0 | D10: 54.18 | E10: 0.0085 | F10: 0.0101 | G10: 0 | H10: 48.37 | I10: 0 | J10: 0.0263 | K10: 0 | L10: 0.0005 | M10: 0.2012 | N10: 102.7966 | O10: 29-636. | P10: Redmoor
A11: 90 | B11: 0.0011 | C11: 0 | D11: 54.23 | E11: 0.0084 | F11: 0.0108 | G11: 0 | H11: 48.16 | I11: 0.0011 | J11: 0.003 | K11: 0 | L11: 0 | M11: 0.213 | N11: 102.6273 | O11: 29-636. | P11: Redmoor
A12: 77 | B12: 0.0045 | C12: 0 | D12: 53.96 | E12: 0.0067 | F12: 0 | G12: 0 | H12: 48.1 | I12: 0 | J12: 0.021 | K12: 0 | L12: 0 | M12: 0.2101 | N12: 102.3022 | O12: 29-636. | P12: Redmoor
A13: 86 | B13: 0.006 | C13: 0 | D13: 53.83 | E13: 0 | F13: 0.0004 | G13: 0 | H13: 47.85 | I13: 0 | J13: 0.0718 | K13: 0 | L13: 0.0014 | M13: 0.3563 | N13: 102.1159 | O13: 29-636. | P13: Redmoor
... A354: 40 | B354: 0.1334 | C354: 0 | D354: 55.22 | E354: 0.0094 | F354: 0 | G354: 0 | H354: 45.64 | I354: 0 | J354: 0.0033 | K354: 0 | L354: 0.0117 | M354: 0.18 | N354: 101.1978 | O354: WE 01A pyrite | P354: Wheal Exmouth

Sheet Pyrrhotite
A1: No. | B1: As | C1: Ga | D1: S | E1: Ag | F1: Sb | G1: Cd | H1: Fe | I1: In | J1: Cu | K1: Sn | L1: Zn | M1: Pb | N1: Total | O1: Sample | P1: Location
A2: 37 | B2: 0.0204 | C2: 0 | D2: 39.44 | E2: 0.013 | F2: 0.0067 | G2: 0 | H2: 63.09 | I2: 0 | J2: 0.0281 | K2: 0 | L2: 0.0067 | M2: 0.1272 | N2: 102.732 | O2: RM82-21-273 pyrrhotite? | P2: Redmoor
A3: 38 | B3: 0.024 | C3: 0 | D3: 39.61 | E3: 0.013 | F3: 0 | G3: 0 | H3: 62.58 | I3: 0 | J3: 0 | K3: 0 | L3: 0.0265 | M3: 0.1444 | N3: 102.3979 | O3: RM82-21-273 pyrrhotite? | P3: Redmoor
A4: 29 | B4: 0.0372 | C4: 0 | D4: 40.22 | E4: 0.0072 | F4: 0.0083 | G4: 0 | H4: 61.93 | I4: 0 | J4: 0.0237 | K4: 0 | L4: 0 | M4: 0.1383 | N4: 102.3646 | O4: RM82-21-273 pyrite | P4: Redmoor
A5: 91 | B5: 0.0119 | C5: 0 | D5: 40.5 | E5: 0.0111 | F5: 0 | G5: 0 | H5: 61.79 | I5: 0 | J5: 0.0098 | K5: 0 | L5: 0 | M5: 0.1731 | N5: 102.4959 | O5: MP-1 pyrrhotite | P5: Red-a-Ven
A6: 50 | B6: 0.0219 | C6: 0 | D6: 40.61 | E6: 0.015 | F6: 0.0046 | G6: 0 | H6: 61.6 | I6: 0 | J6: 0 | K6: 0 | L6: 0.0143 | M6: 0.1472 | N6: 102.4129 | O6: MP-2 pyrrhotite? | P6: Red-a-Ven
A7: 48 | B7: 0.0127 | C7: 0 | D7: 40.66 | E7: 0.0188 | F7: 0 | G7: 0 | H7: 61.59 | I7: 0 | J7: 0 | K7: 0 | L7: 0.0014 | M7: 0.1481 | N7: 102.4309 | O7: MP-2 pyrrhotite? | P7: Red-a-Ven
A8: 40 | B8: 0.0076 | C8: 0 | D8: 40.35 | E8: 0.0058 | F8: 0 | G8: 0 | H8: 61.57 | I8: 0 | J8: 0.0133 | K8: 0 | L8: 0 | M8: 0.1663 | N8: 102.1129 | O8: MP-2 pyrite | P8: Red-a-Ven
A9: 92 | B9: 0.0079 | C9: 0 | D9: 40.44 | E9: 0.0183 | F9: 0 | G9: 0 | H9: 61.55 | I9: 0 | J9: 0.0201 | K9: 0 | L9: 0.012 | M9: 0.1389 | N9: 102.1871 | O9: MP-1 pyrrhotite | P9: Red-a-Ven
A10: 47 | B10: 0.015 | C10: 0 | D10: 40.45 | E10: 0.0034 | F10: 0 | G10: 0 | H10: 61.44 | I10: 0 | J10: 0.0105 | K10: 0 | L10: 0.0134 | M10: 0.1658 | N10: 102.098 | O10: MP-2 pyrrhotite? | P10: Red-a-Ven
A11: 39 | B11: 0.0121 | C11: 0 | D11: 40.57 | E11: 0.0219 | F11: 0.0062 | G11: 0 | H11: 61.43 | I11: 0 | J11: 0.0062 | K11: 0 | L11: 0 | M11: 0.1598 | N11: 102.2061 | O11: MP-2 pyrite | P11: Red-a-Ven
A12: 49 | B12: 0.0046 | C12: 0 | D12: 40.39 | E12: 0.0296 | F12: 0 | G12: 0 | H12: 61.43 | I12: 0.0012 | J12: 0 | K12: 0 | L12: 0.0002 | M12: 0.1544 | N12: 102.0099 | O12: MP-2 pyrrhotite? | P12: Red-a-Ven
A13: 75 | B13: 0.0025 | C13: 0 | D13: 40.36 | E13: 0.0071 | F13: 0 | G13: 0 | H13: 61.29 | I13: 0 | J13: 0 | K13: 0 | L13: 0 | M13: 0.1681 | N13: 101.8276 | O13: MP-1 pyrrhotite | P13: Red-a-Ven
... A23: 25 | B23: 0.0131 | C23: 0 | D23: 40.36 | E23: 0.002 | F23: 0 | G23: 0 | H23: 59.22 | I23: 0 | J23: 0.0079 | K23: 0 | L23: 0 | M23: 0.176 | N23: 99.7791 | O23: MP-04-? | P23: Red-a-Ven
A24: 95 | B24: 0.0328 | C24: 0 | D24: 41.3 | E24: 0.0163 | F24: 0 | G24: 0 | H24: 59.18 | I24: 0.0007 | J24: 0.003 | K24: 0 | L24: 0 | M24: 0.1328 | N24: 100.6655 | O24: WD02-ccp | P24: Wilsey Down | Q24: =H24+L24 -> 59.18
A25: 96 | B25: 0.014 | C25: 0 | D25: 41.54 | E25: 0.0072 | F25: 0 | G25: 0 | H25: 58.44 | I25: 0.0019 | J25: 0.0052 | K25: 0 | L25: 0 | M25: 0.1217 | N25: 100.1299 | O25: WD02-ccp | P25: Wilsey Down | Q25: =H25+L25 -> 58.44

Sheet Chalcopyrite
A1: No. | B1: As | C1: Ga | D1: S | E1: Ag | F1: Sb | G1: Cd | H1: Fe | I1: In | J1: Cu | K1: Sn | L1: Zn | M1: Pb | N1: Total | O1: Sample | P1: Location | Q1: In (corrected) | S1: N | T1: Zn [max] | U1: Zn [ave] | V1: In [max] | W1: In [ave] | X1: Std.dev.
A2: 1 | B2: 0 | C2: 0 | D2: 35.7 | E2: 0.0156 | F2: 0 | G2: 0 | H2: 31.82 | I2: 0.0607 | J2: 35.3 | K2: 0 | L2: 0.0558 | M2: 0.1364 | N2: 103.0884 | O2: 3JD1 chalcopyrite | P2: Wheal Fortune | Q2: =I2-(K2*Standards!$I$15) -> 0.0607 | R2: Wheal Fortune | S2: =COUNT(Q2:Q64) -> 63 | T2: =MAX(L2:L64) -> 0.5924 | U2: =AVERAGE(L2:L64) -> 0.062628571 | V2: =10000*MAX(Q2:Q64) -> 1519 | W2: =10000*AVERAGE(Q2:Q64) -> 602.07937 | X2: =10000*STDEV(Q2:Q64) -> 376.84746
A3: 12 | B3: 0 | C3: 0 | D3: 35.48 | E3: 0.0449 | F3: 0 | G3: 0 | H3: 31.38 | I3: 0.1025 | J3: 35.24 | K3: 0 | L3: 0.0203 | M3: 0.1399 | N3: 102.4076 | O3: 3JD1 chalcopyrite | P3: Wheal Fortune | Q3: =I3-(K3*Standards!$I$15) -> 0.1025
A4: 23 | B4: 0.0002 | C4: 0 | D4: 35.29 | E4: 0.053 | F4: 0 | G4: 0 | H4: 31.44 | I4: 0.0874 | J4: 35.19 | K4: 0 | L4: 0.0397 | M4: 0.1133 | N4: 102.2136 | O4: 3JD1 chalcopyrite | P4: Wheal Fortune | Q4: =I4-(K4*Standards!$I$15) -> 0.0874
A5: 27 | B5: 0 | C5: 0 | D5: 35.4 | E5: 0.0378 | F5: 0 | G5: 0 | H5: 31.36 | I5: 0.1119 | J5: 35.12 | K5: 0 | L5: 0.0572 | M5: 0.1352 | N5: 102.2221 | O5: 3JD1 chalcopyrite | P5: Wheal Fortune | Q5: =I5-(K5*Standards!$I$15) -> 0.1119
A6: 39 | B6: 0 | C6: 0 | D6: 35.53 | E6: 0.0395 | F6: 0 | G6: 0 | H6: 31.47 | I6: 0.0958 | J6: 35.1 | K6: 0 | L6: 0.0417 | M6: 0.14 | N6: 102.4169 | O6: 3JD1 chalcopyrite | P6: Wheal Fortune | Q6: =I6-(K6*Standards!$I$15) -> 0.0958
A7: 20 | B7: 0 | C7: 0 | D7: 35.13 | E7: 0.0362 | F7: 0 | G7: 0 | H7: 31.2 | I7: 0.0995 | J7: 35.09 | K7: 0 | L7: 0.0491 | M7: 0.1464 | N7: 101.7512 | O7: 3JD1 chalcopyrite | P7: Wheal Fortune | Q7: =I7-(K7*Standards!$I$15) -> 0.0995
A8: 3 | B8: 0 | C8: 0 | D8: 35.74 | E8: 0.0243 | F8: 0 | G8: 0 | H8: 31.48 | I8: 0.0712 | J8: 35.09 | K8: 0 | L8: 0.0254 | M8: 0.1344 | N8: 102.5652 | O8: 3JD1 chalcopyrite | P8: Wheal Fortune | Q8: =I8-(K8*Standards!$I$15) -> 0.0712
A9: 26 | B9: 0 | C9: 0 | D9: 35.4 | E9: 0.0515 | F9: 0 | G9: 0 | H9: 31.36 | I9: 0.0964 | J9: 35.07 | K9: 0 | L9: 0.044 | M9: 0.1593 | N9: 102.1811 | O9: 3JD1 chalcopyrite | P9: Wheal Fortune | Q9: =I9-(K9*Standards!$I$15) -> 0.0964
A10: 24 | B10: 0 | C10: 0 | D10: 35.5 | E10: 0.0235 | F10: 0 | G10: 0 | H10: 31.37 | I10: 0.065 | J10: 35.07 | K10: 0 | L10: 0.0163 | M10: 0.1296 | N10: 102.1743 | O10: 3JD1 chalcopyrite | P10: Wheal Fortune | Q10: =I10-(K10*Standards!$I$15) -> 0.065
A11: 46 | B11: 0 | C11: 0 | D11: 35.44 | E11: 0.0347 | F11: 0 | G11: 0 | H11: 31.2 | I11: 0.0991 | J11: 35.06 | K11: 0 | L11: 0.0553 | M11: 0.1209 | N11: 102.0099 | O11: 3JD1 chalcopyrite | P11: Wheal Fortune | Q11: =I11-(K11*Standards!$I$15) -> 0.0991
A12: 28 | B12: 0 | C12: 0 | D12: 35.47 | E12: 0.0448 | F12: 0 | G12: 0 | H12: 31.39 | I12: 0.1048 | J12: 35.06 | K12: 0 | L12: 0.0235 | M12: 0.1488 | N12: 102.2418 | O12: 3JD1 chalcopyrite | P12: Wheal Fortune | Q12: =I12-(K12*Standards!$I$15) -> 0.1048
A13: 41 | B13: 0 | C13: 0 | D13: 35.59 | E13: 0.0288 | F13: 0 | G13: 0 | H13: 31.24 | I13: 0.093 | J13: 35.05 | K13: 0 | L13: 0.0483 | M13: 0.1229 | N13: 102.173 | O13: 3JD1 chalcopyrite | P13: Wheal Fortune | Q13: =I13-(K13*Standards!$I$15) -> 0.093
A14: 22 | B14: 0.0102 | C14: 0 | D14: 35.46 | E14: 0.0678 | F14: 0 | G14: 0 | H14: 31.23 | I14: 0.0921 | J14: 35.05 | K14: 0 | L14: 0.0287 | M14: 0.1408 | N14: 102.0795 | O14: 3JD1 chalcopyrite | P14: Wheal Fortune | Q14: =I14-(K14*Standards!$I$15) -> 0.0921
... A64: 27 | B64: 0 | C64: 0 | D64: 35.43 | E64: 0.0564 | F64: 0 | G64: 0 | H64: 30.63 | I64: 0.0209 | J64: 34.06 | K64: 0 | L64: 0.1586 | M64: 0.146 | N64: 100.5018 | O64: 3JD4-pyrite | P64: Wheal Fortune | Q64: =I64-(K64*Standards!$I$15) -> 0.0209
A65: 25 | B65: 0 | C65: 0 | D65: 35.52 | E65: 0 | F65: 0 | G65: 0 | H65: 30.96 | I65: 0.0444 | J65: 34.76 | K65: 0 | L65: 0.0466 | M65: 0.1107 | N65: 101.4416 | O65: CL-02 chalcopyrite | P65: Cligga Head | Q65: =I65-(K65*Standards!$I$15) -> 0.0444 | R65: Cligga Head | S65: =COUNT(Q65:Q131) -> 67 | T65: =MAX(L65:L131) -> 0.1477 | U65: =AVERAGE(L65:L131) -> 0.033013433 | V65: =10000*MAX(Q65:Q131) -> 539 | W65: =10000*AVERAGE(Q65:Q131) -> 339.71642 | X65: =10000*STDEV(Q65:Q100) -> 42.435497
A66: 23 | B66: 0 | C66: 0 | D66: 35.45 | E66: 0 | F66: 0.01 | G66: 0 | H66: 31.18 | I66: 0.0426 | J66: 34.58 | K66: 0 | L66: 0.0107 | M66: 0.15 | N66: 101.4232 | O66: CL-02 chalcopyrite | P66: Cligga Head | Q66: =I66-(K66*Standards!$I$15) -> 0.0426
A67: 24 | B67: 0 | C67: 0 | D67: 35.53 | E67: 0.0036 | F67: 0 | G67: 0 | H67: 30.9 | I67: 0.0444 | J67: 34.56 | K67: 0 | L67: 0.0392 | M67: 0.1366 | N67: 101.2138 | O67: CL-02 chalcopyrite | P67: Cligga Head | Q67: =I67-(K67*Standards!$I$15) -> 0.0444
A68: 34 | B68: 0 | C68: 0 | D68: 35.34 | E68: 0.0047 | F68: 0 | G68: 0 | H68: 31.01 | I68: 0.0477 | J68: 34.44 | K68: 0 | L68: 0.0461 | M68: 0.1076 | N68: 100.996 | O68: CL-02 chalcopyrite | P68: Cligga Head | Q68: =I68-(K68*Standards!$I$15) -> 0.0477
A69: 22 | B69: 0 | C69: 0 | D69: 35.44 | E69: 0.0008 | F69: 0 | G69: 0 | H69: 31.08 | I69: 0.048 | J69: 34.42 | K69: 0 | L69: 0.0283 | M69: 0.1205 | N69: 101.1375 | O69: CL-02 chalcopyrite | P69: Cligga Head | Q69: =I69-(K69*Standards!$I$15) -> 0.048
A70: 29 | B70: 0 | C70: 0 | D70: 35.36 | E70: 0.0071 | F70: 0 | G70: 0 | H70: 31.11 | I70: 0.0366 | J70: 34.38 | K70: 0 | L70: 0.0327 | M70: 0.1165 | N70: 101.0428 | O70: CL-02 chalcopyrite | P70: Cligga Head | Q70: =I70-(K70*Standards!$I$15) -> 0.0366
A71: 31 | B71: 0 | C71: 0 | D71: 35.35 | E71: 0 | F71: 0 | G71: 0 | H71: 31.07 | I71: 0.0382 | J71: 34.36 | K71: 0 | L71: 0.0283 | M71: 0.1164 | N71: 100.9628 | O71: CL-02 chalcopyrite | P71: Cligga Head | Q71: =I71-(K71*Standards!$I$15) -> 0.0382
A72: 21 | B72: 0 | C72: 0 | D72: 35.39 | E72: 0.0028 | F72: 0 | G72: 0 | H72: 30.96 | I72: 0.042 | J72: 34.35 | K72: 0 | L72: 0.045 | M72: 0.1332 | N72: 100.9229 | O72: CL-02 chalcopyrite | P72: Cligga Head | Q72: =I72-(K72*Standards!$I$15) -> 0.042
A73: 15 | B73: 0 | C73: 0 | D73: 35.65 | E73: 0.0021 | F73: 0.0077 | G73: 0 | H73: 31.07 | I73: 0.0427 | J73: 34.34 | K73: 0 | L73: 0.0337 | M73: 0.1087 | N73: 101.2549 | O73: CL-02 chalcopyrite | P73: Cligga Head | Q73: =I73-(K73*Standards!$I$15) -> 0.0427
A74: 32 | B74: 0 | C74: 0 | D74: 35.59 | E74: 0 | F74: 0 | G74: 0 | H74: 31.25 | I74: 0.0385 | J74: 34.33 | K74: 0 | L74: 0.0477 | M74: 0.1131 | N74: 101.3692 | O74: CL-02 chalcopyrite | P74: Cligga Head | Q74: =I74-(K74*Standards!$I$15) -> 0.0385
A75: 20 | B75: 0.0057 | C75: 0 | D75: 35.35 | E75: 0.0096 | F75: 0 | G75: 0 | H75: 30.85 | I75: 0.0395 | J75: 34.31 | K75: 0 | L75: 0.0109 | M75: 0.1209 | N75: 100.6966 | O75: CL-02 chalcopyrite | P75: Cligga Head | Q75: =I75-(K75*Standards!$I$15) -> 0.0395
A76: 30 | B76: 0 | C76: 0 | D76: 35.46 | E76: 0.0071 | F76: 0 | G76: 0 | H76: 30.92 | I76: 0.0376 | J76: 34.3 | K76: 0 | L76: 0.0075 | M76: 0.1409 | N76: 100.873 | O76: CL-02 chalcopyrite | P76: Cligga Head | Q76: =I76-(K76*Standards!$I$15) -> 0.0376
A77: 33 | B77: 0 | C77: 0 | D77: 35.4 | E77: 0 | F77: 0 | G77: 0 | H77: 31.18 | I77: 0.0407 | J77: 34.27 | K77: 0 | L77: 0.0645 | M77: 0.1105 | N77: 101.0656 | O77: CL-02 chalcopyrite | P77: Cligga Head | Q77: =I77-(K77*Standards!$I$15) -> 0.0407
... A100: 28 | B100: 0 | C100: 0 | D100: 35.31 | E100: 0 | F100: 0.0062 | G100: 0 | H100: 31.22 | I100: 0.05 | J100: 34.42 | K100: 0 | L100: 0.0423 | M100: 0.131 | N100: 101.1794 | O100: CL-02 pyrite | P100: Cligga Head | Q100: =I100-(K100*Standards!$I$15) -> 0.05
A101: 118 | B101: 0 | C101: 0 | D101: 35.78 | E101: 0.0107 | F101: 0 | G101: 0 | H101: 31.16 | I101: 0.0279 | J101: 34.75 | K101: 0 | L101: 0.0309 | M101: 0.1193 | N101: 101.8787 | O101: CL-03 chalcopyrite | P101: Cligga Head | Q101: =I101-(K101*Standards!$I$15) -> 0.0279 | S101: =COUNT(Q101:Q128) -> 28 | W101: =10000*AVERAGE(Q101:Q128) -> 257.71429 | X101: =10000*STDEV(Q101:Q128) -> 39.105609
A102: 131 | B102: 0 | C102: 0 | D102: 35.61 | E102: 0 | F102: 0 | G102: 0 | H102: 31.28 | I102: 0.0338 | J102: 34.74 | K102: 0 | L102: 0.035 | M102: 0.1088 | N102: 101.8076 | O102: CL-03 chalcopyrite | P102: Cligga Head | Q102: =I102-(K102*Standards!$I$15) -> 0.0338
A103: 130 | B103: 0 | C103: 0 | D103: 35.55 | E103: 0 | F103: 0.0003 | G103: 0 | H103: 31.25 | I103: 0.0204 | J103: 34.71 | K103: 0 | L103: 0.0291 | M103: 0.1111 | N103: 101.6708 | O103: CL-03 chalcopyrite | P103: Cligga Head | Q103: =I103-(K103*Standards!$I$15) -> 0.0204
A104: 114 | B104: 0 | C104: 0 | D104: 35.62 | E104: 0.0021 | F104: 0 | G104: 0.0004 | H104: 31.25 | I104: 0.0207 | J104: 34.7 | K104: 0 | L104: 0.0386 | M104: 0.1136 | N104: 101.7453 | O104: CL-03 chalcopyrite | P104: Cligga Head | Q104: =I104-(K104*Standards!$I$15) -> 0.0207
A105: 117 | B105: 0 | C105: 0 | D105: 35.54 | E105: 0.0012 | F105: 0 | G105: 0 | H105: 31.18 | I105: 0.0214 | J105: 34.66 | K105: 0 | L105: 0.0188 | M105: 0.0953 | N105: 101.5166 | O105: CL-03 chalcopyrite | P105: Cligga Head | Q105: =I105-(K105*Standards!$I$15) -> 0.0214
A106: 127 | B106: 0 | C106: 0 | D106: 35.59 | E106: 0 | F106: 0 | G106: 0 | H106: 30.91 | I106: 0.0267 | J106: 34.63 | K106: 0 | L106: 0.0547 | M106: 0.1248 | N106: 101.3362 | O106: CL-03 chalcopyrite | P106: Cligga Head | Q106: =I106-(K106*Standards!$I$15) -> 0.0267
A107: 126 | B107: 0 | C107: 0 | D107: 35.51 | E107: 0 | F107: 0 | G107: 0 | H107: 31.03 | I107: 0.0205 | J107: 34.62 | K107: 0 | L107: 0.0354 | M107: 0.1436 | N107: 101.3594 | O107: CL-03 chalcopyrite | P107: Cligga Head | Q107: =I107-(K107*Standards!$I$15) -> 0.0205
A108: 116 | B108: 0 | C108: 0 | D108: 35.62 | E108: 0 | F108: 0 | G108: 0.0009 | H108: 31.26 | I108: 0.0255 | J108: 34.61 | K108: 0 | L108: 0.022 | M108: 0.1231 | N108: 101.6614 | O108: CL-03 chalcopyrite | P108: Cligga Head | Q108: =I108-(K108*Standards!$I$15) -> 0.0255
A109: 124 | B109: 0 | C109: 0 | D109: 35.4 | E109: 0.0125 | F109: 0 | G109: 0 | H109: 31.35 | I109: 0.0306 | J109: 34.61 | K109: 0 | L109: 0 | M109: 0.1095 | N109: 101.5126 | O109: CL-03 chalcopyrite | P109: Cligga Head | Q109: =I109-(K109*Standards!$I$15) -> 0.0306
A110: 125 | B110: 0 | C110: 0 | D110: 35.49 | E110: 0.015 | F110: 0 | G110: 0.0003 | H110: 31.09 | I110: 0.0229 | J110: 34.56 | K110: 0 | L110: 0.0106 | M110: 0.1187 | N110: 101.3074 | O110: CL-03 chalcopyrite | P110: Cligga Head | Q110: =I110-(K110*Standards!$I$15) -> 0.0229
A111: 128 | B111: 0 | C111: 0 | D111: 35.52 | E111: 0 | F111: 0 | G111: 0 | H111: 31.34 | I111: 0.0213 | J111: 34.55 | K111: 0 | L111: 0.0162 | M111: 0.157 | N111: 101.6044 | O111: CL-03 chalcopyrite | P111: Cligga Head | Q111: =I111-(K111*Standards!$I$15) -> 0.0213
...

Sheet Stannite-kesterite
A1: No. | B1: As | C1: Ga | D1: S | E1: Ag | F1: Sb | G1: Cd | H1: Fe | I1: In | J1: Cu | K1: Sn | L1: Zn | M1: Pb | N1: Total | O1: Sample | P1: Location | Q1: In (corrected) | R1: In (corrected) | S1: In (corrected) | T1: In (corrected) | V1: n | W1: Zn [max] | X1: Zn [ave] | Y1: In [max] | Z1: In [ave]
A2: 292 | B2: 0 | C2: 0 | D2: 32.12 | E2: 0 | F2: 0 | G2: 0 | H2: 20.3 | I2: 0.2926 | J2: 28.59 | K2: 15.21 | L2: 1.75 | M2: 0.0901 | N2: 98.3528 | O2: RJS-BK-1 stannite inc in ccp | P2: Botallack | Q2: =I2-(K2*Standards!$I$15) -> 0.25894788 | V2: =COUNT(Q2:Q28) -> 27 | W2: =MAX(L2:L28) -> 9.2 | X2: =AVERAGE(L2:L28) -> 3.1114815 | Y2: =10000*MAX(Q2:Q28) -> 6814.6775 | Z2: =10000*AVERAGE(Q2:Q28) -> 3167.8139
A3: 295 | B3: 0 | C3: 0 | D3: 30.01 | E3: 0 | F3: 0 | G3: 0 | H3: 11.99 | I3: 0.3424 | J3: 27.6 | K3: 26.99 | L3: 3.01 | M3: 0.0775 | N3: 100.0198 | O3: RJS-BK-1 stannite inc in ccp | P3: Botallack | Q3: =I3-(K3*Standards!$I$15) -> 0.28268462
A4: 296 | B4: 0 | C4: 0 | D4: 29.61 | E4: 0 | F4: 0 | G4: 0 | H4: 11.28 | I4: 0.3278 | J4: 27.18 | K4: 27.48 | L4: 2.82 | M4: 0.0801 | N4: 98.7779 | O4: RJS-BK-1 stannite inc in ccp | P4: Botallack | Q4: =I4-(K4*Standards!$I$15) -> 0.2670005
A5: 293 | B5: 0 | C5: 0 | D5: 29.82 | E5: 0 | F5: 0 | G5: 0 | H5: 11.86 | I5: 0.3713 | J5: 26.89 | K5: 27.04 | L5: 2.84 | M5: 0.07 | N5: 98.8913 | O5: RJS-BK-1 stannite inc in ccp | P5: Botallack | Q5: =I5-(K5*Standards!$I$15) -> 0.311474
A6: 294 | B6: 0 | C6: 0 | D6: 29.76 | E6: 0 | F6: 0 | G6: 0 | H6: 11.6 | I6: 0.3487 | J6: 26.88 | K6: 27.75 | L6: 2.9 | M6: 0.0673 | N6: 99.3061 | O6: RJS-BK-1 stannite inc in ccp | P6: Botallack | Q6: =I6-(K6*Standards!$I$15) -> 0.28730312
A7: 300 | B7: 0 | C7: 0 | D7: 29.8 | E7: 0 | F7: 0 | G7: 0 | H7: 11.18 | I7: 0.3449 | J7: 26.83 | K7: 27.61 | L7: 3.18 | M7: 0.0717 | N7: 99.0167 | O7: RJS-BK-1 stannite inc in ccp | P7: Botallack | Q7: =I7-(K7*Standards!$I$15) -> 0.28381287
A8: 297 | B8: 0 | C8: 0 | D8: 29.87 | E8: 0 | F8: 0 | G8: 0 | H8: 11.7 | I8: 0.3271 | J8: 26.74 | K8: 26.85 | L8: 3.28 | M8: 0.0851 | N8: 98.8522 | O8: RJS-BK-1 stannite inc in ccp | P8: Botallack | Q8: =I8-(K8*Standards!$I$15) -> 0.26769437
A9: 298 | B9: 0 | C9: 0 | D9: 29.68 | E9: 0 | F9: 0 | G9: 0 | H9: 11.21 | I9: 0.2994 | J9: 26.55 | K9: 27.6 | L9: 3.2 | M9: 0.1056 | N9: 98.645 | O9: RJS-BK-1 stannite inc in ccp | P9: Botallack | Q9: =I9-(K9*Standards!$I$15) -> 0.238335
A10: 311 | B10: 0 | C10: 0 | D10: 29.74 | E10: 0 | F10: 0 | G10: 0 | H10: 10.9 | I10: 0.3195 | J10: 26.39 | K10: 28.13 | L10: 4.33 | M10: 0.0776 | N10: 99.8872 | O10: RJS-BK-1 stannite inc in sphalerite | P10: Botallack | Q10: =I10-(K10*Standards!$I$15) -> 0.25726237
A11: 299 | B11: 0 | C11: 0 | D11: 29.63 | E11: 0 | F11: 0 | G11: 0 | H11: 11.4 | I11: 0.3393 | J11: 26.32 | K11: 27.28 | L11: 3.55 | M11: 0.0758 | N11: 98.5952 | O11: RJS-BK-1 stannite inc in ccp | P11: Botallack | Q11: =I11-(K11*Standards!$I$15) -> 0.278943
A12: 275 | B12: 0 | C12: 0 | D12: 30.08 | E12: 0 | F12: 0 | G12: 0 | H12: 12.96 | I12: 0.282 | J12: 26.26 | K12: 27.47 | L12: 1.3 | M12: 0.069 | N12: 98.4211 | O12: RJS-BK-1 stannite rim to ccp | P12: Botallack | Q12: =I12-(K12*Standards!$I$15) -> 0.22122262
A13: 274 | B13: 0 | C13: 0 | D13: 30.06 | E13: 0 | F13: 0 | G13: 0 | H13: 12.98 | I13: 0.3437 | J13: 26.16 | K13: 27.15 | L13: 1.26 | M13: 0.0793 | N13: 98.0331 | O13: RJS-BK-1 stannite rim to ccp | P13: Botallack | Q13: =I13-(K13*Standards!$I$15) -> 0.28363063
A14: 291 | B14: 0 | C14: 0 | D14: 31.35 | E14: 0 | F14: 0 | G14: 0 | H14: 15.74 | I14: 0.3861 | J14: 26.16 | K14: 18.61 | L14: 6.19 | M14: 0.0927 | N14: 98.5289 | O14: RJS-BK-1 stannite inc in ccp | P14: Botallack | Q14: =I14-(K14*Standards!$I$15) -> 0.34492537
... A28: 312 | B28: 0 | C28: 0 | D28: 30.16 | E28: 0 | F28: 0 | G28: 0 | H28: 10.7 | I28: 0.3017 | J28: 24.42 | K28: 25.53 | L28: 9.2 | M28: 0.066 | N28: 100.3776 | O28: RJS-BK-1 stannite inc in sphalerite | P28: Botallack | Q28: =I28-(K28*Standards!$I$15) -> 0.24521488
A29: 104 | B29: 0 | C29: 0 | D29: 30.33 | E29: 0 | F29: 0 | G29: 0 | H29: 7.61 | I29: 0.1087 | J29: 29.83 | K29: 27.29 | L29: 6.35 | M29: 0.0931 | N29: 101.6117 | O29: CL-10 kesterite | P29: Cligga Head | R29: =I29-(K29*Standards!$I$15) -> 0.048320875 | V29: =COUNT(R29:R45) -> 17 | W29: =MAX(L29:L45) -> 13.61 | X29: =AVERAGE(L29:L45) -> 8.3670588 | Y29: =10000*MAX(R29:R45) -> 659.78375 | Z29: =10000*AVERAGE(R29:R45) -> 434.80441
A30: 102 | B30: 0 | C30: 0 | D30: 30.07 | E30: 0 | F30: 0 | G30: 0 | H30: 5.84 | I30: 0.1036 | J30: 29.61 | K30: 27.28 | L30: 8.72 | M30: 0.0922 | N30: 101.7157 | O30: CL-10 kesterite | P30: Cligga Head | R30: =I30-(K30*Standards!$I$15) -> 0.043243
A31: 101 | B31: 0 | C31: 0 | D31: 29.98 | E31: 0 | F31: 0 | G31: 0 | H31: 5.92 | I31: 0.1077 | J31: 29.59 | K31: 27.34 | L31: 8.51 | M31: 0.1014 | N31: 101.549 | O31: CL-10 kesterite | P31: Cligga Head | R31: =I31-(K31*Standards!$I$15) -> 0.04721025
A32: 96 | B32: 0 | C32: 0 | D32: 30.1 | E32: 0 | F32: 0 | G32: 0 | H32: 7.41 | I32: 0.1056 | J32: 29.52 | K32: 27.12 | L32: 7.12 | M32: 0.0773 | N32: 101.4529 | O32: CL-10 kesterite | P32: Cligga Head | R32: =I32-(K32*Standards!$I$15) -> 0.045597
A33: 99 | B33: 0 | C33: 0 | D33: 30.44 | E33: 0 | F33: 0 | G33: 0 | H33: 6.39 | I33: 0.0926 | J33: 29.48 | K33: 27.29 | L33: 8.15 | M33: 0.1116 | N33: 101.9542 | O33: CL-10 kesterite | P33: Cligga Head | R33: =I33-(K33*Standards!$I$15) -> 0.032220875
A34: 97 | B34: 0 | C34: 0 | D34: 30.04 | E34: 0 | F34: 0 | G34: 0 | H34: 7.03 | I34: 0.1182 | J34: 29.47 | K34: 27.28 | L34: 7.43 | M34: 0.1109 | N34: 101.479 | O34: CL-10 kesterite | P34: Cligga Head | R34: =I34-(K34*Standards!$I$15) -> 0.057843
A35: 93 | B35: 0 | C35: 0 | D35: 30.09 | E35: 0 | F35: 0 | G35: 0 | H35: 7.61 | I35: 0.1188 | J35: 29.46 | K35: 27.12 | L35: 6.89 | M35: 0.1125 | N35: 101.4013 | O35: CL-10 kesterite | P35: Cligga Head | R35: =I35-(K35*Standards!$I$15) -> 0.058797
A36: 103 | B36: 0 | C36: 0 | D36: 30.19 | E36: 0 | F36: 0 | G36: 0 | H36: 6.4 | I36: 0.089 | J36: 29.43 | K36: 27.09 | L36: 8.12 | M36: 0.0892 | N36: 101.4082 | O36: CL-10 kesterite | P36: Cligga Head | R36: =I36-(K36*Standards!$I$15) -> 0.029063375
A37: 105 | B37: 0 | C37: 0 | D37: 29.86 | E37: 0 | F37: 0 | G37: 0 | H37: 6.8 | I37: 0.0991 | J37: 29.43 | K37: 27.29 | L37: 7.65 | M37: 0.0639 | N37: 101.193 | O37: CL-10 kesterite | P37: Cligga Head | R37: =I37-(K37*Standards!$I$15) -> 0.038720875
A38: 100 | B38: 0 | C38: 0 | D38: 29.93 | E38: 0 | F38: 0 | G38: 0 | H38: 4.43 | I38: 0.1021 | J38: 29.35 | K38: 27.34 | L38: 10.21 | M38: 0.0777 | N38: 101.4397 | O38: CL-10 kesterite | P38: Cligga Head | R38: =I38-(K38*Standards!$I$15) -> 0.04161025
A39: 94 | B39: 0 | C39: 0 | D39: 30.08 | E39: 0 | F39: 0 | G39: 0 | H39: 7.63 | I39: 0.1149 | J39: 29.32 | K39: 27.52 | L39: 6.62 | M39: 0.0849 | N39: 101.3698 | O39: CL-10 kesterite | P39: Cligga Head | R39: =I39-(K39*Standards!$I$15) -> 0.054012
A40: 95 | B40: 0 | C40: 0 | D40: 30.12 | E40: 0 | F40: 0 | G40: 0 | H40: 7.46 | I40: 0.1127 | J40: 29.27 | K40: 27.38 | L40: 6.72 | M40: 0.0952 | N40: 101.1579 | O40: CL-10 kesterite | P40: Cligga Head | R40: =I40-(K40*Standards!$I$15) -> 0.05212175
A41: 78 | B41: 0 | C41: 0 | D41: 30.03 | E41: 0 | F41: 0 | G41: 0 | H41: 5.51 | I41: 0.097 | J41: 29.24 | K41: 27.11 | L41: 9.18 | M41: 0.0976 | N41: 101.2645 | O41: CL-10 lollingite | P41: Cligga Head | R41: =I41-(K41*Standards!$I$15) -> 0.037019125
... A45: 76 | B45: 0 | C45: 0 | D45: 30.1 | E45: 0.102 | F45: 0 | G45: 0 | H45: 2.52 | I45: 0.0782 | J45: 28.36 | K45: 26.28 | L45: 13.61 | M45: 0.0859 | N45: 101.136 | O45: CL-10 lollingite | P45: Cligga Head | R45: =I45-(K45*Standards!$I$15) -> 0.0200555
A46: 9 | B46: 0 | C46: 0 | D46: 26.6 | E46: 0 | F46: 0 | G46: 0 | H46: 12.68 | I46: 0.1044 | J46: 26.69 | K46: 33.87 | L46: 0.37 | M46: 0.0842 | N46: 100.3985 | O46: HD-01 stannite | P46: Hingston Down | S46: =I46-(K46*Standards!$I$15) -> 0.029462625 | V46: =COUNT(S46:S61) -> 16 | W46: =MAX(L46:L61) -> 2.87 | X46: =AVERAGE(L46:L61) -> 1.6463125 | Y46: =10000*MAX(S46:S61) -> 687.0325 | Z46: =10000*AVERAGE(S46:S61) -> 252.9825
A47: 20 | B47: 0 | C47: 0 | D47: 29.99 | E47: 0 | F47: 0 | G47: 0 | H47: 13.94 | I47: 0.0714 | J47: 30.57 | K47: 28.24 | L47: 0.4354 | M47: 0.0898 | N47: 103.3365 | O47: HD-01 stannite? | P47: Hingston Down | S47: =I47-(K47*Standards!$I$15) -> 0.008919
A48: 21 | B48: 0 | C48: 0 | D48: 30.15 | E48: 0 | F48: 0 | G48: 0 | H48: 14.3 | I48: 0.0808 | J48: 30.71 | K48: 27.98 | L48: 0.5489 | M48: 0.0875 | N48: 103.8571 | O48: HD-01 stannite? | P48: Hingston Down | S48: =I48-(K48*Standards!$I$15) -> 0.01889425
A49: 19 | B49: 0 | C49: 0 | D49: 29.96 | E49: 0 | F49: 0 | G49: 0 | H49: 14.09 | I49: 0.0809 | J49: 30.53 | K49: 28.15 | L49: 0.7067 | M49: 0.0875 | N49: 103.605 | O49: HD-01 stannite? | P49: Hingston Down | S49: =I49-(K49*Standards!$I$15) -> 0.018618125
A50: 25 | B50: 0 | C50: 0 | D50: 29.74 | E50: 0 | F50: 0 | G50: 0 | H50: 13.29 | I50: 0.0911 | J50: 30.52 | K50: 28.05 | L50: 1.36 | M50: 0.0827 | N50: 103.1338 | O50: HD-01 stannite? | P50: Hingston Down | S50: =I50-(K50*Standards!$I$15) -> 0.029039375
A51: 12 | B51: 0.1057 | C51: 0 | D51: 29.75 | E51: 0 | F51: 0 | G51: 0 | H51: 13.91 | I51: 0.0931 | J51: 30.14 | K51: 27.42 | L51: 1.37 | M51: 0.0851 | N51: 102.8738 | O51: HD-01 stannite | P51: Hingston Down | S51: =I51-(K51*Standards!$I$15) -> 0.03243325
A52: 13 | B52: 0 | C52: 0 | D52: 29.85 | E52: 0 | F52: 0 | G52: 0 | H52: 13.19 | I52: 0.0999 | J52: 30.07 | K52: 28.09 | L52: 1.48 | M52: 0.0955 | N52: 102.8753 | O52: HD-01 stannite | P52: Hingston Down | S52: =I52-(K52*Standards!$I$15) -> 0.037750875
A53: 22 | B53: 0 | C53: 0 | D53: 30.3 | E53: 0 | F53: 0 | G53: 0 | H53: 13.2 | I53: 0.089 | J53: 30.79 | K53: 28.2 | L53: 1.48 | M53: 0.0949 | N53: 104.1538 | O53: HD-01 stannite? | P53: Hingston Down | S53: =I53-(K53*Standards!$I$15) -> 0.0266075
A54: 28 | B54: 0 | C54: 0 | D54: 29.84 | E54: 0 | F54: 0 | G54: 0 | H54: 13.37 | I54: 0.0702 | J54: 30.69 | K54: 27.36 | L54: 1.93 | M54: 0.1038 | N54: 103.3639 | O54: HD-01 stannite | P54: Hingston Down | S54: =I54-(K54*Standards!$I$15) -> 0.009666
A55: 23 | B55: 0 | C55: 0 | D55: 29.96 | E55: 0 | F55: 0 | G55: 0 | H55: 12.42 | I55: 0.0789 | J55: 30.72 | K55: 28.25 | L55: 2.08 | M55: 0.101 | N55: 103.6098 | O55: HD-01 stannite? | P55: Hingston Down | S55: =I55-(K55*Standards!$I$15) -> 0.016396875
A56: 16 | B56: 0 | C56: 0 | D56: 29.97 | E56: 0 | F56: 0 | G56: 0 | H56: 12.49 | I56: 0.0745 | J56: 30.28 | K56: 28.16 | L56: 2.1 | M56: 0.0587 | N56: 103.1331 | O56: HD-01 stannite | P56: Hingston Down | S56: =I56-(K56*Standards!$I$15) -> 0.012196
...

Sheet Sphalerite
A1: No. | B1: As | C1: Ga | D1: S | E1: Ag | F1: Sb | G1: Cd | H1: Fe | I1: In | J1: Cu | K1: Sn | L1: Zn | M1: Pb | N1: Total | O1: Sample | Q1: Zn+Fe | R1: In (corrected) | S1: Ga corrected | T1: Location | U1: Number | V1: Fe [max] | W1: Fe [ave] | X1: Cu [max] | Y1: Cu [ave] | Z1: In [max] | AA1: In [ave] | AB1: Cd [max] | AC1: Cd [ave] | AD1: Ga [max] | AE1: Ga [ave]
A2: 40 | B2: 0 | C2: 0.0246 | D2: 33.85 | E2: 0.1414 | F2: 0 | G2: 0.2995 | H2: 6.74 | I2: 0.1053 | J2: 2.45 | K2: 1.18 | L2: 58.69 | M2: 0.1309 | N2: 103.6116 | O2: 3JD1 sph in ccp | Q2: =H2+L2 -> 65.43 | R2: =I2-(K2*Standards!$I$15) -> 0.10268925 | S2: =C2-(I2*0.05) -> 0.019335 | T2: Wheal Fortune | U2: =COUNT(R2:R6) -> 5 | V2: =MAX(H2:H6) -> 10.52 | W2: =AVERAGE(H2:H6) -> 7.496 | X2: =MAX(J2:J6) -> 2.45 | Y2: =AVERAGE(J2:J6) -> 0.96198 | Z2: =10000*MAX(R2:R6) -> 4634 | AA2: =10000*AVERAGE(R2:R6) -> 1769.5145 | AB2: =10000*MAX(G2:G6) -> 2995 | AC2: =10000*AVERAGE(G2:G6) -> 1962.8 | AD2: =10000*MAX(S2:S6) -> 431.6 | AE2: =10000*AVERAGE(S2:S6) -> 336.98
A3: 19 | B3: 0 | C3: 0.0629 | D3: 33.99 | E3: 0.0733 | F3: 0 | G3: 0.1436 | H3: 9.69 | I3: 0.4634 | J3: 0.2844 | K3: 0 | L3: 57.36 | M3: 0.0847 | N3: 102.1523 | O3: 3JD1 sph in ccp | Q3: =H3+L3 -> 67.05 | R3: =I3-(K3*Standards!$I$15) -> 0.4634 | S3: =C3-(I3*0.05) -> 0.03973 | T3: Wheal Fortune
A4: 18 | B4: 0 | C4: 0.0533 | D4: 34.14 | E4: 0.0772 | F4: 0 | G4: 0.1433 | H4: 10.52 | I4: 0.2028 | J4: 0.1743 | K4: 0 | L4: 57.11 | M4: 0.1407 | N4: 102.5615 | O4: 3JD1 sph in ccp | Q4: =H4+L4 -> 67.63 | R4: =I4-(K4*Standards!$I$15) -> 0.2028 | S4: =C4-(I4*0.05) -> 0.04316 | T4: Wheal Fortune
A5: 11 | B5: 0 | C5: 0.0399 | D5: 34.35 | E5: 0.0594 | F5: 0 | G5: 0.1275 | H5: 4.83 | I5: 0 | J5: 0.1212 | K5: 0 | L5: 63.59 | M5: 0.132 | N5: 103.2499 | O5: 3JD1 sphalerite | Q5: =H5+L5 -> 68.42 | R5: =I5-(K5*Standards!$I$15) -> 0 | S5: =C5-(I5*0.05) -> 0.0399 | T5: Wheal Fortune
A6: 52 | B6: 0 | C6: 0.0323 | D6: 33.54 | E6: 0.1317 | F6: 0 | G6: 0.2675 | H6: 5.7 | I6: 0.1187 | J6: 1.78 | K6: 1.28 | L6: 59.29 | M6: 0.1326 | N6: 102.2727 | O6: 3JD1 sphalerite | Q6: =H6+L6 -> 64.99 | R6: =I6-(K6*Standards!$I$15) -> 0.115868 | S6: =C6-(I6*0.05) -> 0.026365 | T6: Wheal Fortune
A7: 3 | B7: 0 | C7: 0.0633 | D7: 33.84 | E7: 0.061 | F7: 0 | G7: 0.1447 | H7: 0.9652 | I7: 0 | J7: 0 | K7: 0 | L7: 66.71 | M7: 0.1185 | N7: 101.9026 | O7: CAL-01 Sphalerite | Q7: =H7+L7 -> 67.6752 | R7: =I7-(K7*Standards!$I$15) -> 0 | S7: =C7-(I7*0.05) -> 0.0633 | T7: West Chiverton | U7: =COUNT(R7:R10) -> 4 | V7: =MAX(H7:H10) -> 8.52 | W7: =AVERAGE(H7:H10) -> 4.6888 | X7: =MAX(J7:J10) -> 4.58 | Y7: =AVERAGE(J7:J10) -> 1.4975 | Z7: =10000*MAX(R7:R10) -> 1494 | AA7: =10000*AVERAGE(R7:R10) -> 703.25 | AB7: =10000*MAX(G7:G10) -> 1447 | AC7: =10000*AVERAGE(G7:G10) -> 990.25 | AD7: =10000*MAX(S7:S10) -> 633 | AE7: =10000*AVERAGE(S7:S10) -> 489.3375
A8: 19 | B8: 0 | C8: 0.0633 | D8: 34.01 | E8: 0.0543 | F8: 0 | G8: 0.1388 | H8: 3.05 | I8: 0.0097 | J8: 0 | K8: 0 | L8: 63.74 | M8: 0.1126 | N8: 101.1786 | O8: CAL-01 Sphalerite | Q8: =H8+L8 -> 66.79 | R8: =I8-(K8*Standards!$I$15) -> 0.0097 | S8: =C8-(I8*0.05) -> 0.062815 | T8: West Chiverton
A9: 21 | B9: 0 | C9: 0.0454 | D9: 34.24 | E9: 0.0356 | F9: 0 | G9: 0.0604 | H9: 6.22 | I9: 0.1222 | J9: 1.41 | K9: 0 | L9: 59.54 | M9: 0.1184 | N9: 101.7919 | O9: CAL-01 sphalerite | Q9: =H9+L9 -> 65.76 | R9: =I9-(K9*Standards!$I$15) -> 0.1222 | S9: =C9-(I9*0.05) -> 0.03929 | T9: West Chiverton
A10: 20 | B10: 0 | C10: 0.0378 | D10: 34.23 | E10: 0.0636 | F10: 0 | G10: 0.0522 | H10: 8.52 | I10: 0.1494 | J10: 4.58 | K10: 0 | L10: 52.2 | M10: 0.1136 | N10: 99.9466 | O10: CAL-01 sphalerite | Q10: =H10+L10 -> 60.72 | R10: =I10-(K10*Standards!$I$15) -> 0.1494 | S10: =C10-(I10*0.05) -> 0.03033 | T10: West Chiverton
A11: 111 | B11: 0 | C11: 0.0665 | D11: 34.02 | E11: 0.0454 | F11: 0 | G11: 0.1265 | H11: 0.3127 | I11: 0.0436 | J11: 0.0553 | K11: 0 | L11: 67.4 | M11: 0.0827 | N11: 102.1526 | O11: CL-10 sphalerite | Q11: =H11+L11 -> 67.7127 | R11: =I11-(K11*Standards!$I$15) -> 0.0436 | S11: =C11-(I11*0.05) -> 0.06432 | T11: Cligga Head | U11: =COUNT(R11:R25) -> 15 | V11: =MAX(H11:H25) -> 1.95 | W11: =AVERAGE(H11:H25) -> 1.5782133 | X11: =MAX(J11:J25) -> 0.399 | Y11: =AVERAGE(J11:J25) -> 0.081906667 | Z11: =10000*MAX(R11:R25) -> 743 | AA11: =10000*AVERAGE(R11:R25) -> 322.33477 | AB11: =10000*MAX(G11:G25) -> 1538 | AC11: =10000*AVERAGE(G11:G25) -> 1400.0667 | AD11: =10000*MAX(S11:S25) -> 643.2 | AE11: =10000*AVERAGE(S11:S25) -> 514.71333
A12: 112 | B12: 0 | C12: 0.0644 | D12: 34 | E12: 0.0449 | F12: 0 | G12: 0.1422 | H12: 0.3405 | I12: 0.0743 | J12: 0.0529 | K12: 0 | L12: 67.23 | M12: 0.1144 | N12: 102.0636 | O12: CL-10 sphalerite | Q12: =H12+L12 -> 67.5705 | R12: =I12-(K12*Standards!$I$15) -> 0.0743 | S12: =C12-(I12*0.05) -> 0.060685 | T12: Cligga Head
A13: 109 | B13: 0 | C13: 0.0532 | D13: 34.05 | E13: 0.0501 | F13: 0 | G13: 0.132 | H13: 1.59 | I13: 0.0265 | J13: 0.0503 | K13: 0 | L13: 66.32 | M13: 0.0946 | N13: 102.3666 | O13: CL-10 sphalerite | Q13: =H13+L13 -> 67.91 | R13: =I13-(K13*Standards!$I$15) -> 0.0265 | S13: =C13-(I13*0.05) -> 0.051875 | T13: Cligga Head
A14: 86 | B14: 0 | C14: 0.0467 | D14: 34.07 | E14: 0.0553 | F14: 0 | G14: 0.1291 | H14: 1.68 | I14: 0.025 | J14: 0.0161 | K14: 0 | L14: 66.02 | M14: 0.0889 | N14: 102.1311 | O14: CL-10 sphalerite | Q14: =H14+L14 -> 67.7 | R14: =I14-(K14*Standards!$I$15) -> 0.025 | S14: =C14-(I14*0.05) -> 0.04545 | T14: Cligga Head
A15: 85 | B15: 0 | C15: 0.0512 | D15: 34.16 | E15: 0.0525 | F15: 0 | G15: 0.1327 | H15: 1.72 | I15: 0.0297 | J15: 0.0291 | K15: 0 | L15: 66.01 | M15: 0.0744 | N15: 102.2596 | O15: CL-10 sphalerite | Q15: =H15+L15 -> 67.73 | R15: =I15-(K15*Standards!$I$15) -> 0.0297 | S15: =C15-(I15*0.05) -> 0.049715 | T15: Cligga Head
A16: 91 | B16: 0 | C16: 0.0502 | D16: 34.14 | E16: 0.0489 | F16: 0 | G16: 0.1344 | H16: 1.62 | I16: 0.0244 | J16: 0.0618 | K16: 0.0018 | L16: 66.01 | M16: 0.0957 | N16: 102.1871 | O16: CL-10 sphalerite | Q16: =H16+L16 -> 67.63 | R16: =I16-(K16*Standards!$I$15) -> 0.024396018 | S16: =C16-(I16*0.05) -> 0.04898 | T16: Cligga Head
A17: 87 | B17: 0 | C17: 0.0476 | D17: 33.96 | E17: 0.0533 | F17: 0 | G17: 0.1442 | H17: 1.87 | I17: 0.0305 | J17: 0.0415 | K17: 0 | L17: 65.96 | M17: 0.101 | N17: 102.208 | O17: CL-10 sphalerite | Q17: =H17+L17 -> 67.83 | R17: =I17-(K17*Standards!$I$15) -> 0.0305 | S17: =C17-(I17*0.05) -> 0.046075 | T17: Cligga Head
A18: 92 | B18: 0 | C18: 0.0504 | D18: 33.99 | E18: 0.0493 | F18: 0 | G18: 0.1323 | H18: 1.59 | I18: 0.0264 | J18: 0.0744 | K18: 0.0167 | L18: 65.85 | M18: 0.1049 | N18: 101.8844 | O18: CL-10 sphalerite | Q18: =H18+L18 -> 67.44 | R18: =I18-(K18*Standards!$I$15) -> 0.026363051 | S18: =C18-(I18*0.05) -> 0.04908 | T18: Cligga Head
A19: 88 | B19: 0 | C19: 0.062 | D19: 34.14 | E19: 0.0658 | F19: 0 | G19: 0.1523 | H19: 1.95 | I19: 0.0321 | J19: 0.0594 | K19: 0 | L19: 65.79 | M19: 0.0907 | N19: 102.3422 | O19: CL-10 sphalerite | Q19: =H19+L19 -> 67.74 | R19: =I19-(K19*Standards!$I$15) -> 0.0321 | S19: =C19-(I19*0.05) -> 0.060395 | T19: Cligga Head
A20: 89 | B20: 0 | C20: 0.0502 | D20: 34 | E20: 0.0472 | F20: 0 | G20: 0.138 | H20: 1.72 | I20: 0.0374 | J20: 0.0307 | K20: 0 | L20: 65.79 | M20: 0.0777 | N20: 101.8912 | O20: CL-10 sphalerite | Q20: =H20+L20 -> 67.51 | R20: =I20-(K20*Standards!$I$15) -> 0.0374 | S20: =C20-(I20*0.05) -> 0.04833 | T20: Cligga Head
A21: 83 | B21: 0 | C21: 0.0496 | D21: 34.1 | E21: 0.0533 | F21: 0 | G21: 0.1506 | H21: 1.72 | I21: 0.0358 | J21: 0.0349 | K21: 0 | L21: 65.77 | M21: 0.0872 | N21: 102.0013 | O21: CL-10 sphalerite | Q21: =H21+L21 -> 67.49 | R21: =I21-(K21*Standards!$I$15) -> 0.0358 | S21: =C21-(I21*0.05) -> 0.04781 | T21: Cligga Head
A22: 107 | B22: 0 | C22: 0.0521 | D22: 34.05 | E22: 0.0665 | F22: 0 | G22: 0.1369 | H22: 1.89 | I22: 0.025 | J22: 0.1859 | K22: 0.1199 | L22: 65.77 | M22: 0.0775 | N22: 102.3737 | O22: CL-10 sphalerite | Q22: =H22+L22 -> 67.66 | R22: =I22-(K22*Standards!$I$15) -> 0.024734721 | S22: =C22-(I22*0.05) -> 0.05085 | T22: Cligga Head
A23: 84 | B23: 0 | C23: 0.0499 | D23: 34.13 | E23: 0.0715 | F23: 0 | G23: 0.1508 | H23: 1.89 | I23: 0.0267 | J23: 0.0444 | K23: 0 | L23: 65.65 | M23: 0.0754 | N23: 102.0886 | O23: CL-10 sphalerite | Q23: =H23+L23 -> 67.54 | R23: =I23-(K23*Standards!$I$15) -> 0.0267 | S23: =C23-(I23*0.05) -> 0.048565 | T23: Cligga Head
... A25: 90 | B25: 0 | C25: 0.0423 | D25: 34.21 | E25: 0.0483 | F25: 0 | G25: 0.1443 | H25: 1.9 | I25: 0.0263 | J25: 0.399 | K25: 0.3578 | L25: 65.34 | M25: 0.0755 | N25: 102.5434 | O25: CL-10 sphalerite | Q25: =H25+L25 -> 67.24 | R25: =I25-(K25*Standards!$I$15) -> 0.025508368 | S25: =C25-(I25*0.05) -> 0.040985 | T25: Cligga Head
A26: 47 | B26: 0 | C26: 0.0614 | D26: 33.23 | E26: 0.0474 | F26: 0 | G26: 0.1947 | H26: 1.02 | I26: 0.8222 | J26: 6.06 | K26: 1.32 | L26: 58.77 | M26: 0.2979 | N26: 101.8235 | O26: Crofty 13 grey sphalerite | Q26: =H26+L26 -> 59.79 | R26: =I26-(K26*Standards!$I$15) -> 0.8192795 | S26: =C26-(I26*0.05) -> 0.02029 | T26: Dolcoath | U26: =COUNT(R26:R84) -> 59 | V26: =MAX(H26:H84) -> 12.01 | W26: =AVERAGE(H26:H84) -> 8.516122 | X26: =MAX(J26:J84) -> 7.27 | Y26: =AVERAGE(J26:J84) -> 0.84922373 | Z26: =10000*MAX(R26:R84) -> 14200 | AA26: =10000*AVERAGE(R26:R84) -> 1416.0218 | AB26: =10000*MAX(G26:G84) -> 9474 | AC26: =10000*AVERAGE(G26:G84) -> 1645.6949 | AD26: =10000*MAX(S26:S84) -> 610.15 | AE26: =10000*AVERAGE(S26:S84) -> 348.44407
A27: 2 | B27: 0 | C27: 0.0611 | D27: 33.76 | E27: 0.0007 | F27: 0 | G27: 0.026 | H27: 0.0573 | I27: 0.0017 | J27: 0.2459 | K27: 0 | L27: 67.56 | M27: 0.1017 | N27: 101.8143 | O27: Crofty 13 sphalerite | Q27: =H27+L27 -> 67.6173 | R27: =I27-(K27*Standards!$I$15) -> 0.0017 | S27: =C27-(I27*0.05) -> 0.061015 | T27: Dolcoath
A28: 8 | B28: 0 | C28: 0.0463 | D28: 33.83 | E28: 0.0051 | F28: 0 | G28: 0.0099 | H28: 0.2654 | I28: 0.0085 | J28: 0.0894 | K28: 0 | L28: 67.25 | M28: 0.1204 | N28: 101.6249 | O28: Crofty 13 sphalerite | Q28: =H28+L28 -> 67.5154 | R28: =I28-(K28*Standards!$I$15) -> 0.0085 | S28: =C28-(I28*0.05) -> 0.045875 | T28: Dolcoath
A29: 1 | B29: 0 | C29: 0.0558 | D29: 33.53 | E29: 0.0504 | F29: 0 | G29: 0.1043 | H29: 0.1258 | I29: 0.0709 | J29: 0.1749 | K29: 0 | L29: 67.14 | M29: 0.1065 | N29: 101.3586 | O29: Crofty 13 sphalerite | Q29: =H29+L29 -> 67.2658 | R29: =I29-(K29*Standards!$I$15) -> 0.0709 | S29: =C29-(I29*0.05) -> 0.052255 | T29: Dolcoath
A30: 50 | B30: 0 | C30: 0.0551 | D30: 33.83 | E30: 0.0889 | F30: 0 | G30: 0.2656 | H30: 0.1815 | I30: 0.1437 | J30: 0.3543 | K30: 0.0559 | L30: 67.09 | M30: 0.0766 | N30: 102.1415 | O30: Crofty 13 sphalerite | Q30: =H30+L30 -> 67.2715 | R30: =I30-(K30*Standards!$I$15) -> 0.14357632 | S30: =C30-(I30*0.05) -> 0.047915 | T30: Dolcoath
A31: 7 | B31: 0 | C31: 0.059 | D31: 33.59 | E31: 0.0161 | F31: 0 | G31: 0.0115 | H31: 0.0612 | I31: 0.024 | J31: 0.2054 | K31: 0 | L31: 67.06 | M31: 0.0982 | N31: 101.1253 | O31: Crofty 13 sphalerite | Q31: =H31+L31 -> 67.1212 | R31: =I31-(K31*Standards!$I$15) -> 0.024 | S31: =C31-(I31*0.05) -> 0.0578 | T31: Dolcoath
A32: 48 | B32: 0 | C32: 0.0613 | D32: 33.68 | E32: 0.1661 | F32: 0 | G32: 0.4217 | H32: 0.0701 | I32: 0.2353 | J32: 0.5734 | K32: 0.001 | L32: 66.66 | M32: 0.1006 | N32: 101.9694 | O32: Crofty 13 sphalerite | Q32: =H32+L32 -> 66.7301 | R32: =I32-(K32*Standards!$I$15) -> 0.23529779 | S32: =C32-(I32*0.05) -> 0.049535 | T32: Dolcoath
A33: 49 | B33: 0 | C33: 0.0613 | D33: 33.74 | E33: 0.3754 | F33: 0 | G33: 0.9001 | H33: 0.149 | I33: 0.2001 | J33: 0.4356 | K33: 0 | L33: 66.56 | M33: 0.0901 | N33: 102.5115 | O33: Crofty 13 sphalerite | Q33: =H33+L33 -> 66.709 | R33: =I33-(K33*Standards!$I$15) -> 0.2001 | S33: =C33-(I33*0.05) -> 0.051295 | T33: Dolcoath
A34: 6 | B34: 0.0285 | C34: 0.0585 | D34: 33.19 | E34: 0.4109 | F34: 0 | G34: 0.9474 | H34: 0.7333 | I34: 0.239 | J34: 3.65 | K34: 0 | L34: 62.53 | M34: 0.1893 | N34: 101.9768 | O34: Crofty 13 sphalerite | Q34: =H34+L34 -> 63.2633 | R34: =I34-(K34*Standards!$I$15) -> 0.239 | S34: =C34-(I34*0.05) -> 0.04655 | T34: Dolcoath
A35: 9 | B35: 0.1712 | C35: 0.0318 | D35: 32.25 | E35: 0.0949 | F35: 0 | G35: 0.2088 | H35: 0.7876 | I35: 0.1794 | J35: 5.08 | K35: 0.0112 | L35: 61.86 | M35: 0.2492 | N35: 100.924 | O35: Crofty 13 sphalerite | Q35: =H35+L35 -> 62.6476 | R35: =I35-(K35*Standards!$I$15) -> 0.17937522 | S35: =C35-(I35*0.05) -> 0.02283 | T35: Dolcoath
A36: 81 | B36: 0 | C36: 0.0277 | D36: 34.59 | E36: 0.0747 | F36: 0 | G36: 0.1285 | H36: 9.83 | I36: 0.0556 | J36: 0.4907 | K36: 0 | L36: 57.57 | M36: 0.1155 | N36: 102.8826 | O36: Crofty 14 sph in py | Q36: =H36+L36 -> 67.4 | R36: =I36-(K36*Standards!$I$15) -> 0.0556 | S36: =C36-(I36*0.05) -> 0.02492 | T36: Dolcoath
A37: 83 | B37: 0 | C37: 0.0233 | D37: 34.93 | E37: 0.0479 | F37: 0 | G37: 0.1309 | H37: 11.56 | I37: 0.0109 | J37: 0.0119 | K37: 0 | L37: 56.49 | M37: 0.1261 | N37: 103.331 | O37: Crofty 14 sph in py | Q37: =H37+L37 -> 68.05 | R37: =I37-(K37*Standards!$I$15) -> 0.0109 | S37: =C37-(I37*0.05) -> 0.022755 | T37: Dolcoath
A38: 84 | B38: 0 | C38: 0.0249 | D38: 34.64 | E38: 0.0552 | F38: 0.017 | G38: 0.1252 | H38: 11.59 | I38: 0.0051 | J38: 0.0856 | K38: 0 | L38: 56.12 | M38: 0.1025 | N38: 102.7654 | O38: Crofty 14 sph in py | Q38: =H38+L38 -> 67.71 | R38: =I38-(K38*Standards!$I$15) -> 0.0051 | S38: =C38-(I38*0.05) -> 0.024645 | T38: Dolcoath
... A84: 90 | B84: 0 | C84: 0.1217 | D84: 33.28 | E84: 0 | F84: 0 | G84: 0.133 | H84: 5.24 | I84: 1.42 | J84: 6.94 | K84: 0 | L84: 53.61 | M84: 0.0466 | N84: 100.7912 | O84: DC-02 sphalerite | Q84: =H84+L84 -> 58.85 | R84: =I84-(K84*Standards!$I$15) -> 1.42 | S84: =C84-(I84*0.05) -> 0.0507 | T84: Dolcoath
A85: 27 | B85: 0 | C85: 0.063 | D85: 32.07 | E85: 0.1695 | F85: 0 | G85: 0.3749 | H85: 0.1076 | I85: 0 | J85: 0 | K85: 0 | L85: 69.06 | M85: 0.1048 | N85: 101.9497 | O85: GS-1 sphalerite | Q85: =H85+L85 -> 69.1676 | R85: =I85-(K85*Standards!$I$15) -> 0 | S85: =C85-(I85*0.05) -> 0.063 | T85: Greystone | U85: =COUNT(R85:R102) -> 18 | V85: =MAX(H85:H102) -> 0.4322 | W85: =AVERAGE(H85:H102) -> 0.17896111 | X85: =MAX(J85:J102) -> 0.3349 | Y85: =AVERAGE(J85:J102) -> 0.039322222 | Z85: =10000*MAX(R85:R102) -> 97 | AA85: =10000*AVERAGE(R85:R102) -> 16 | AB85: =10000*MAX(G85:G102) -> 4928 | AC85: =10000*AVERAGE(G85:G102) -> 4088.4444 | AD85: =10000*MAX(S85:S102) -> 630 | AE85: =10000*AVERAGE(S85:S102) -> 467.58889
A86: 25 | B86: 0 | C86: 0.0356 | D86: 34.07 | E86: 0.2308 | F86: 0.0038 | G86: 0.4518 | H86: 0.1447 | I86: 0 | J86: 0 | K86: 0 | L86: 68 | M86: 0.1314 | N86: 103.068 | O86: GS-1 sphalerite | Q86: =H86+L86 -> 68.1447 | R86: =I86-(K86*Standards!$I$15) -> 0 | S86: =C86-(I86*0.05) -> 0.0356 | T86: Greystone
...

Sheet Cassiterite
A1: No. | B1: As | C1: Ga | D1: S | E1: Ag | F1: Sb | G1: Cd | H1: Fe | I1: In | J1: Cu | K1: Sn | L1: Zn | M1: Pb | N1: Total | O1: Sample | Q1: In (ppm) | R1: In/Sn | S1: In (corrected) | T1: Location | U1: n | V1: Fe [max] | W1: Fe [ave] | X1: In [max] | Y1: In [ave]
A2: 2 | B2: 0 | C2: 0 | D2: 0.0046 | E2: 0 | F2: 0 | G2: 0 | H2: 0.0166 | I2: 0.3238 | J2: 0.0769 | K2: 98.66 | L2: 0.1204 | M2: 0.0189 | N2: 99.2213 | O2: Sn-std | Q2: =10000*I2 -> 3238 | R2: =I2/K2 -> 0.0032819785 | S2: =10000*(I2-(K2*Standards!I$15)) -> 1055.1475
A3: 3 | B3: 0 | C3: 0 | D3: 0.0015 | E3: 0 | F3: 0 | G3: 0 | H3: 0.0075 | I3: 0.295 | J3: 0.0637 | K3: 98.47 | L3: 0.0906 | M3: 0.0061 | N3: 98.9345 | O3: Sn-std | Q3: =10000*I3 -> 2950 | R3: =I3/K3 -> 0.0029958363 | S3: =10000*(I3-(K3*Standards!I$15)) -> 771.35125
A4: 6 | B4: 0 | C4: 0 | D4: 0.0024 | E4: 0 | F4: 0 | G4: 0 | H4: 0.0049 | I4: 0.2737 | J4: 0.0159 | K4: 94.6 | L4: 0.0515 | M4: 0.0261 | N4: 94.9745 | O4: Sn-std | Q4: =10000*I4 -> 2737 | R4: =I4/K4 -> 0.0028932347 | S4: =10000*(I4-(K4*Standards!I$15)) -> 643.975
A5: 1 | B5: 0 | C5: 0 | D5: 0.0019 | E5: 0 | F5: 0 | G5: 0 | H5: 0.0016 | I5: 0.3195 | J5: 0.054 | K5: 98.6 | L5: 0.0442 | M5: 0 | N5: 99.0212 | O5: Sn-std | Q5: =10000*I5 -> 3195 | R5: =I5/K5 -> 0.0032403651 | S5: =10000*(I5-(K5*Standards!I$15)) -> 1013.475
A6: 8 | B6: 0 | C6: 0 | D6: 0 | E6: 0 | F6: 0 | G6: 0 | H6: 0.0006 | I6: 0.2878 | J6: 0.0313 | K6: 97.64 | L6: 0.088 | M6: 0 | N6: 98.0478 | O6: Sn-std | Q6: =10000*I6 -> 2878 | R6: =I6/K6 -> 0.0029475625 | S6: =10000*(I6-(K6*Standards!I$15)) -> 717.715
A7: 4 | B7: 0 | C7: 0 | D7: 0.0133 | E7: 0 | F7: 0 | G7: 0 | H7: 0 | I7: 0.2866 | J7: 0.1029 | K7: 98.18 | L7: 0.1355 | M7: 0.0115 | N7: 98.7299 | O7: Sn-std | Q7: =10000*I7 -> 2866 | R7: =I7/K7 -> 0.0029191281 | S7: =10000*(I7-(K7*Standards!I$15)) -> 693.7675
